Workbook

Sheet Слайд 1 тренды категорий (2)
B1: Продажи за июль-декабрь 2023, шт | C1: Продажи за январь - июнь 2024, шт | D1: Продажи за июль-декабрь 2024, шт. | E1: Продажи за январь - июнь 2025, шт | J1: Доход за июль-декабрь 2023, грн. | K1: Доход за январь - июнь 2024, грн. | L1: Доход за июль-декабрь 2024, грн. | M1: Доход за январь - июнь 2025, грн | R1: Маржа за июль-декабрь 2023, грн. | S1: Маржа за январь - июнь 2024, грн. | T1: Маржа за июль-декабрь 2024, грн. | U1: Маржа за январь - июнь 2025, грн
A2: Категория | B2: июль-декабрь 2023 | C2: январь-июнь 2024 | D2: июль-декабрь 2024 | E2: январь-июнь 2025 | F2: I 2024 к II 2023 | G2: II 2024 к I 2024 | H2: I 2025 к II 2024 | I2: I 2025 к I 2024 | J2: июль-декабрь 2023 | K2: январь-июнь 2024 | L2: июль-декабрь 2024 | M2: январь-июнь 2025 | N2: I 2024 к II 2023 | O2: II 2024 к I 2024 | P2: I 2025 к II 2024 | Q2: I 2025 к I 2024 | R2: июль-декабрь 2023 | S2: январь-июнь 2024 | T2: июль-декабрь 2024 | U2: январь-июнь 2025 | V2: I 2024 к II 2023 | W2: II 2024 к I 2024 | X2: I 2025 к II 2024 | Y2: I 2025 к I 2024
A3: КРЕСЛА РУКОВОДИТЕЛЯ | B3: 26725 | C3: 19187 | D3: 11862 | E3: 17643 | F3: =IFERROR(C3/B3-1,"") -> -0.282058 | G3: =IFERROR(D3/C3-1,"") -> -0.38176891 | H3: =IFERROR(E3/D3-1,"") -> 0.48735458 | I3: =IFERROR(E3/C3-1,"") -> -0.080471152 | J3: 1.0435148e+08 | K3: 76149864 | L3: 48903591 | M3: 80667045 | N3: =IFERROR(K3/J3-1,"") -> -0.27025604 | O3: =IFERROR(L3/K3-1,"") -> -0.35779805 | P3: =IFERROR(M3/L3-1,"") -> 0.64951169 | Q3: =IFERROR(M3/K3-1,"") -> 0.059319619 | R3: 41678917 | S3: 29293819 | T3: 20819003 | U3: 37262622 | V3: =IFERROR(S3/R3-1,"") -> -0.29715499 | W3: =IFERROR(T3/S3-1,"") -> -0.28930389 | X3: =IFERROR(U3/T3-1,"") -> 0.78983703 | Y3: =IFERROR(U3/S3-1,"") -> 0.2720302
A4: КРЕСЛА ОПЕРАТОРСКИЕ | B4: 54881 | C4: 31299 | D4: 22967 | E4: 25652 | F4: =IFERROR(C4/B4-1,"") -> -0.42969334 | G4: =IFERROR(D4/C4-1,"") -> -0.26620659 | H4: =IFERROR(E4/D4-1,"") -> 0.11690687 | I4: =IFERROR(E4/C4-1,"") -> -0.1804211 | J4: 1.0179829e+08 | K4: 64253469 | L4: 46903609 | M4: 55936401 | N4: =IFERROR(K4/J4-1,"") -> -0.36881584 | O4: =IFERROR(L4/K4-1,"") -> -0.27002215 | P4: =IFERROR(M4/L4-1,"") -> 0.19258204 | Q4: =IFERROR(M4/K4-1,"") -> -0.12944153 | R4: 36343788 | S4: 23321133 | T4: 18351033 | U4: 24679206 | V4: =IFERROR(S4/R4-1,"") -> -0.35831858 | W4: =IFERROR(T4/S4-1,"") -> -0.21311575 | X4: =IFERROR(U4/T4-1,"") -> 0.34484019 | Y4: =IFERROR(U4/S4-1,"") -> 0.058233567
A5: СТУЛЬЯ ПОСЕТИТЕЛЬСКИЕ | B5: 107526 | C5: 64256 | D5: 58364 | E5: 67148 | F5: =IFERROR(C5/B5-1,"") -> -0.4024143 | G5: =IFERROR(D5/C5-1,"") -> -0.091695717 | H5: =IFERROR(E5/D5-1,"") -> 0.15050374 | I5: =IFERROR(E5/C5-1,"") -> 0.04500747 | J5: 77193435 | K5: 51648131 | L5: 46674389 | M5: 54214244 | N5: =IFERROR(K5/J5-1,"") -> -0.33092587 | O5: =IFERROR(L5/K5-1,"") -> -0.096300531 | P5: =IFERROR(M5/L5-1,"") -> 0.16154161 | Q5: =IFERROR(M5/K5-1,"") -> 0.049684536 | R5: 33002287 | S5: 22045621 | T5: 19928779 | U5: 25520626 | V5: =IFERROR(S5/R5-1,"") -> -0.33199717 | W5: =IFERROR(T5/S5-1,"") -> -0.096020966 | X5: =IFERROR(U5/T5-1,"") -> 0.28059152 | Y5: =IFERROR(U5/S5-1,"") -> 0.15762789
A6: КРЕСЛА/СТУЛЬЯ ОБЕДЕННЫЕ | B6: 78009 | C6: 58965 | D6: 40156 | E6: 47534 | F6: =IFERROR(C6/B6-1,"") -> -0.24412568 | G6: =IFERROR(D6/C6-1,"") -> -0.31898584 | H6: =IFERROR(E6/D6-1,"") -> 0.18373344 | I6: =IFERROR(E6/C6-1,"") -> -0.19386076 | J6: 66683260 | K6: 49237455 | L6: 27945548 | M6: 43255800 | N6: =IFERROR(K6/J6-1,"") -> -0.26162195 | O6: =IFERROR(L6/K6-1,"") -> -0.43243313 | P6: =IFERROR(M6/L6-1,"") -> 0.54786015 | Q6: =IFERROR(M6/K6-1,"") -> -0.12148586 | R6: 24715841 | S6: 17502361 | T6: 10575011 | U6: 19039783 | V6: =IFERROR(S6/R6-1,"") -> -0.29185657 | W6: =IFERROR(T6/S6-1,"") -> -0.39579513 | X6: =IFERROR(U6/T6-1,"") -> 0.80045037 | Y6: =IFERROR(U6/S6-1,"") -> 0.087840878
A7: СТОЛЫ ОБЕДЕННЫЕ | B7: 6808 | C7: 7086 | D7: 1539 | E7: 5029 | F7: =IFERROR(C7/B7-1,"") -> 0.040834313 | G7: =IFERROR(D7/C7-1,"") -> -0.78281118 | H7: =IFERROR(E7/D7-1,"") -> 2.2677063 | I7: =IFERROR(E7/C7-1,"") -> -0.29029071 | J7: 13274969 | K7: 14856408 | L7: 3462301.8 | M7: 11801728 | N7: =IFERROR(K7/J7-1,"") -> 0.11912935 | O7: =IFERROR(L7/K7-1,"") -> -0.76694892 | P7: =IFERROR(M7/L7-1,"") -> 2.4086365 | Q7: =IFERROR(M7/K7-1,"") -> -0.20561359 | R7: 4245578 | S7: 4785922.3 | T7: 1236084.8 | U7: 5069490 | V7: =IFERROR(S7/R7-1,"") -> 0.12727227 | W7: =IFERROR(T7/S7-1,"") -> -0.74172485 | X7: =IFERROR(U7/T7-1,"") -> 3.1012477 | Y7: =IFERROR(U7/S7-1,"") -> 0.059250361
A8: МЕБЕЛЬ КОРПУСНАЯ | B8: 3932.5 | C8: 2361 | D8: 1622 | E8: 1498 | F8: =IFERROR(C8/B8-1,"") -> -0.39961856 | G8: =IFERROR(D8/C8-1,"") -> -0.31300296 | H8: =IFERROR(E8/D8-1,"") -> -0.076448829 | I8: =IFERROR(E8/C8-1,"") -> -0.36552308 | J8: 10065870 | K8: 5679902 | L8: 4934825.8 | M8: 4877919.2 | N8: =IFERROR(K8/J8-1,"") -> -0.43572666 | O8: =IFERROR(L8/K8-1,"") -> -0.13117765 | P8: =IFERROR(M8/L8-1,"") -> -0.011531623 | Q8: =IFERROR(M8/K8-1,"") -> -0.14119658 | R8: 4222096.4 | S8: 2198456.6 | T8: 2256819.9 | U8: 1975349.1 | V8: =IFERROR(S8/R8-1,"") -> -0.4792974 | W8: =IFERROR(T8/S8-1,"") -> 0.026547401 | X8: =IFERROR(U8/T8-1,"") -> -0.1247201 | Y8: =IFERROR(U8/S8-1,"") -> -0.10148369
A9: КРЕСЛА ДЕТСКИЕ | B9: 8503 | C9: 3416 | D9: 3012 | E9: 2295 | F9: =IFERROR(C9/B9-1,"") -> -0.59825944 | G9: =IFERROR(D9/C9-1,"") -> -0.11826698 | H9: =IFERROR(E9/D9-1,"") -> -0.23804781 | I9: =IFERROR(E9/C9-1,"") -> -0.32816159 | J9: 14549396 | K9: 6480186.7 | L9: 4671519.1 | M9: 4709913.3 | N9: =IFERROR(K9/J9-1,"") -> -0.55460786 | O9: =IFERROR(L9/K9-1,"") -> -0.27910733 | P9: =IFERROR(M9/L9-1,"") -> 0.0082187841 | Q9: =IFERROR(M9/K9-1,"") -> -0.27318247 | R9: 5928440.8 | S9: 2412246.8 | T9: 1930051.5 | U9: 2236567.4 | V9: =IFERROR(S9/R9-1,"") -> -0.59310603 | W9: =IFERROR(T9/S9-1,"") -> -0.19989468 | X9: =IFERROR(U9/T9-1,"") -> 0.15881226 | Y9: =IFERROR(U9/S9-1,"") -> -0.072828138
A10: ШКОЛЬНАЯ МЕБЕЛЬ | B10: 4475 | C10: 1917 | D10: 12977 | E10: 3475 | F10: =IFERROR(C10/B10-1,"") -> -0.57162011 | G10: =IFERROR(D10/C10-1,"") -> 5.7694314 | H10: =IFERROR(E10/D10-1,"") -> -0.73221854 | I10: =IFERROR(E10/C10-1,"") -> 0.81272822 | J10: 4239927.1 | K10: 1956771.5 | L10: 11816811 | M10: 3111446.5 | N10: =IFERROR(K10/J10-1,"") -> -0.53848937 | O10: =IFERROR(L10/K10-1,"") -> 5.0389327 | P10: =IFERROR(M10/L10-1,"") -> -0.73669322 | Q10: =IFERROR(M10/K10-1,"") -> 0.5900919 | R10: 1910384.6 | S10: 842104.97 | T10: 3649948.1 | U10: 1181067.2 | V10: =IFERROR(S10/R10-1,"") -> -0.55919611 | W10: =IFERROR(T10/S10-1,"") -> 3.3343149 | X10: =IFERROR(U10/T10-1,"") -> -0.67641535 | Y10: =IFERROR(U10/S10-1,"") -> 0.40251777
A11: КРЕСЛА И СТУЛЬЯ СПЕЦИАЛЬНЫЕ | B11: 2133 | C11: 1664 | D11: 1467 | E11: 1156 | F11: =IFERROR(C11/B11-1,"") -> -0.21987811 | G11: =IFERROR(D11/C11-1,"") -> -0.11838942 | H11: =IFERROR(E11/D11-1,"") -> -0.21199727 | I11: =IFERROR(E11/C11-1,"") -> -0.30528846 | J11: 3900269.6 | K11: 3364475.8 | L11: 3463375.8 | M11: 2953696 | N11: =IFERROR(K11/J11-1,"") -> -0.13737353 | O11: =IFERROR(L11/K11-1,"") -> 0.029395364 | P11: =IFERROR(M11/L11-1,"") -> -0.14716272 | Q11: =IFERROR(M11/K11-1,"") -> -0.12209325 | R11: 1710718.3 | S11: 1421269.6 | T11: 1324346 | U11: 1271305.7 | V11: =IFERROR(S11/R11-1,"") -> -0.16919717 | W11: =IFERROR(T11/S11-1,"") -> -0.068195105 | X11: =IFERROR(U11/T11-1,"") -> -0.040050189 | Y11: =IFERROR(U11/S11-1,"") -> -0.10551407
A12: КОМПЛЕКТУЮЩИЕ СТОЛОВ, КРЕСЕЛ И СТУЛЬЕВ ОБЕДЕННЫХ | B12: 15093 | C12: 9342 | D12: 6957 | E12: 7040 | F12: =IFERROR(C12/B12-1,"") -> -0.38103757 | G12: =IFERROR(D12/C12-1,"") -> -0.25529865 | H12: =IFERROR(E12/D12-1,"") -> 0.01193043 | I12: =IFERROR(E12/C12-1,"") -> -0.24641404 | J12: 5550667.4 | K12: 3071901.3 | L12: 2897245.4 | M12: 2445725 | N12: =IFERROR(K12/J12-1,"") -> -0.44657083 | O12: =IFERROR(L12/K12-1,"") -> -0.056855965 | P12: =IFERROR(M12/L12-1,"") -> -0.15584472 | Q12: =IFERROR(M12/K12-1,"") -> -0.20383998 | R12: 2409463.1 | S12: 1294452.3 | T12: 1293366.7 | U12: 1171741.6 | V12: =IFERROR(S12/R12-1,"") -> -0.46276318 | W12: =IFERROR(T12/S12-1,"") -> -0.00083867503 | X12: =IFERROR(U12/T12-1,"") -> -0.094037611 | Y12: =IFERROR(U12/S12-1,"") -> -0.094797419
A13: СТУЛЬЯ БАРНЫЕ | B13: 1764 | C13: 1714 | D13: 689 | E13: 1201 | F13: =IFERROR(C13/B13-1,"") -> -0.028344671 | G13: =IFERROR(D13/C13-1,"") -> -0.59801634 | H13: =IFERROR(E13/D13-1,"") -> 0.74310595 | I13: =IFERROR(E13/C13-1,"") -> -0.29929988 | J13: 3099852.1 | K13: 3128273.7 | L13: 1220087.1 | M13: 2434195.9 | N13: =IFERROR(K13/J13-1,"") -> 0.0091686728 | O13: =IFERROR(L13/K13-1,"") -> -0.6099807 | P13: =IFERROR(M13/L13-1,"") -> 0.99510007 | Q13: =IFERROR(M13/K13-1,"") -> -0.22187247 | R13: 1175832.6 | S13: 1174931.8 | T13: 526905.54 | U13: 1086764 | V13: =IFERROR(S13/R13-1,"") -> -0.00076616556 | W13: =IFERROR(T13/S13-1,"") -> -0.55154371 | X13: =IFERROR(U13/T13-1,"") -> 1.0625404 | Y13: =IFERROR(U13/S13-1,"") -> -0.07504076
A14: МЯГКАЯ МЕБЕЛЬ | B14: 444 | C14: 570 | D14: 630 | E14: 431 | F14: =IFERROR(C14/B14-1,"") -> 0.28378378 | G14: =IFERROR(D14/C14-1,"") -> 0.10526316 | H14: =IFERROR(E14/D14-1,"") -> -0.31587302 | I14: =IFERROR(E14/C14-1,"") -> -0.24385965 | J14: 2405433.6 | K14: 2617486.3 | L14: 2979997.7 | M14: 2066375.7 | N14: =IFERROR(K14/J14-1,"") -> 0.08815572 | O14: =IFERROR(L14/K14-1,"") -> 0.13849599 | P14: =IFERROR(M14/L14-1,"") -> -0.3065848 | Q14: =IFERROR(M14/K14-1,"") -> -0.21054958 | R14: 1086348.6 | S14: 892745.76 | T14: 1199134.5 | U14: 881718.07 | V14: =IFERROR(S14/R14-1,"") -> -0.17821428 | W14: =IFERROR(T14/S14-1,"") -> 0.34319824 | X14: =IFERROR(U14/T14-1,"") -> -0.26470463 | Y14: =IFERROR(U14/S14-1,"") -> -0.012352554
... A18: Общий итог | B18: 315257.5 | C18: 204938 | D18: 164270 | E18: 181722 | F18: =IFERROR(C18/B18-1,"") -> -0.34993458 | G18: =IFERROR(D18/C18-1,"") -> -0.1984405 | H18: =IFERROR(E18/D18-1,"") -> 0.10623973 | I18: =IFERROR(E18/C18-1,"") -> -0.11328304 | J18: 4.1703718e+08 | K18: 2.9029148e+08 | L18: 2.1029576e+08 | M18: 2.7197929e+08 | N18: =IFERROR(K18/J18-1,"") -> -0.30391941 | O18: =IFERROR(L18/K18-1,"") -> -0.27557035 | P18: =IFERROR(M18/L18-1,"") -> 0.29331799 | Q18: =IFERROR(M18/K18-1,"") -> -0.063082097 | R18: 1.6188722e+08 | S18: 1.0957985e+08 | T18: 84557444 | U18: 1.2280211e+08 | V18: =IFERROR(S18/R18-1,"") -> -0.32310996 | W18: =IFERROR(T18/S18-1,"") -> -0.22834858 | X18: =IFERROR(U18/T18-1,"") -> 0.45229209 | Y18: =IFERROR(U18/S18-1,"") -> 0.12066326
A19: Общий итог, млн. грн. | B19: 315257.5 | C19: 204938 | D19: 164270 | E19: 181722 | F19: =IFERROR(C19/B19-1,"") -> -0.34993458 | G19: =IFERROR(D19/C19-1,"") -> -0.1984405 | H19: =IFERROR(E19/D19-1,"") -> 0.10623973 | I19: =IFERROR(E19/C19-1,"") -> -0.11328304 | J19: =MROUND(J18/1000000,1) -> 417 | K19: =MROUND(K18/1000000,1) -> 290 | L19: =MROUND(L18/1000000,1) -> 210 | M19: =MROUND(M18/1000000,1) -> 272 | N19: =IFERROR(K19/J19-1,"") -> -0.30455635 | O19: =IFERROR(L19/K19-1,"") -> -0.27586207 | P19: =IFERROR(M19/L19-1,"") -> 0.2952381 | Q19: =IFERROR(M19/K19-1,"") -> -0.062068966 | R19: =MROUND(R18/1000000,1) -> 162 | S19: =MROUND(S18/1000000,1) -> 110 | T19: =MROUND(T18/1000000,1) -> 85 | U19: =MROUND(U18/1000000,1) -> 123 | V19: =IFERROR(S19/R19-1,"") -> -0.32098765 | W19: =IFERROR(T19/S19-1,"") -> -0.22727273 | X19: =IFERROR(U19/T19-1,"") -> 0.44705882 | Y19: =IFERROR(U19/S19-1,"") -> 0.11818182
A21: Общая динамика | B21: сравниваем 1 полугодие 2025 с 1 полугодием 2024 и со втормым полугодием 2024 | L21: КРЕСЛА/СТУЛЬЯ ОБЕДЕННЫЕ
A35: КРЕСЛА РУКОВОДИТЕЛЯ
L37: ШКОЛЬНАЯ МЕБЕЛЬ
A49: КРЕСЛА ОПЕРАТОРСКИЕ
A63: СТУЛЬЯ ПОСЕТИТЕЛЬСКИЕ

Sheet Слайд 1 тренды категорий
A1: Категория | B1: Доля в доходах за январь - июнь 2025
A2: КРЕСЛА РУКОВОДИТЕЛЯ | B2: 0.28335783
A3: КРЕСЛА ОПЕРАТОРСКИЕ | B3: 0.1964869
A4: СТУЛЬЯ ПОСЕТИТЕЛЬСКИЕ | B4: 0.1904375
A5: КРЕСЛА/СТУЛЬЯ ОБЕДЕННЫЕ | B5: 0.15194395
A6: СТОЛЫ ОБЕДЕННЫЕ | B6: 0.041455741
A7: МЕБЕЛЬ КОРПУСНАЯ | B7: 0.017134588
A8: КРЕСЛА ДЕТСКИЕ | B8: 0.016544437
A9: ШКОЛЬНАЯ МЕБЕЛЬ | B9: 0.010929528
A10: КРЕСЛА И СТУЛЬЯ СПЕЦИАЛЬНЫЕ | B10: 0.0103754
A11: КОМПЛЕКТУЮЩИЕ СТОЛОВ, КРЕСЕЛ И СТУЛЬЕВ ОБЕДЕННЫХ | B11: 0.0085910588
A12: СТУЛЬЯ БАРНЫЕ | B12: 0.0085505606
A13: МЯГКАЯ МЕБЕЛЬ | B13: 0.0072585246
... A17: Общий итог | B17: 0.95537727
A18: Прочие | B18: =100%-SUM(B2:B5) -> 0.17777381
B45: Продажи за июль-декабрь 2023, шт | C45: Продажи за январь - июнь 2024, шт | D45: Продажи за июль-декабрь 2024, шт. | E45: Продажи за январь - июнь 2025, шт | J45: Доход за июль-декабрь 2023, грн. | K45: Доход за январь - июнь 2024, грн. | L45: Доход за июль-декабрь 2024, грн. | M45: Доход за январь - июнь 2025, грн | R45: Маржа за июль-декабрь 2023, грн. | S45: Маржа за январь - июнь 2024, грн. | T45: Маржа за июль-декабрь 2024, грн. | U45: Маржа за январь - июнь 2025, грн
A46: Категория | B46: июль-декабрь 2023 | C46: январь-июнь 2024 | D46: июль-декабрь 2024 | E46: январь-июнь 2025 | F46: I 2024 к II 2023 | G46: II 2024 к I 2024 | H46: I 2025 к II 2024 | I46: I 2025 к I 2024 | J46: июль-декабрь 2023 | K46: январь-июнь 2024 | L46: июль-декабрь 2024 | M46: январь-июнь 2025 | N46: I 2024 к II 2023 | O46: II 2024 к I 2024 | P46: I 2025 к II 2024 | Q46: I 2025 к I 2024 | R46: июль-декабрь 2023 | S46: январь-июнь 2024 | T46: июль-декабрь 2024 | U46: январь-июнь 2025 | V46: I 2024 к II 2023 | W46: II 2024 к I 2024 | X46: I 2025 к II 2024 | Y46: I 2025 к I 2024
A47: КРЕСЛА РУКОВОДИТЕЛЯ | B47: 26725 | C47: 19187 | D47: 11862 | E47: 17643 | F47: =IFERROR(C47/B47-1,"") -> -0.282058 | G47: =IFERROR(D47/C47-1,"") -> -0.38176891 | H47: =IFERROR(E47/D47-1,"") -> 0.48735458 | I47: =IFERROR(E47/C47-1,"") -> -0.080471152 | J47: 1.0435148e+08 | K47: 76149864 | L47: 48903591 | M47: 80667045 | N47: =IFERROR(K47/J47-1,"") -> -0.27025604 | O47: =IFERROR(L47/K47-1,"") -> -0.35779805 | P47: =IFERROR(M47/L47-1,"") -> 0.64951169 | Q47: =IFERROR(M47/K47-1,"") -> 0.059319619 | R47: 41678917 | S47: 29293819 | T47: 20819003 | U47: 37262622 | V47: =IFERROR(S47/R47-1,"") -> -0.29715499 | W47: =IFERROR(T47/S47-1,"") -> -0.28930389 | X47: =IFERROR(U47/T47-1,"") -> 0.78983703 | Y47: =IFERROR(U47/S47-1,"") -> 0.2720302
A48: КРЕСЛА ОПЕРАТОРСКИЕ | B48: 54881 | C48: 31299 | D48: 22967 | E48: 25652 | F48: =IFERROR(C48/B48-1,"") -> -0.42969334 | G48: =IFERROR(D48/C48-1,"") -> -0.26620659 | H48: =IFERROR(E48/D48-1,"") -> 0.11690687 | I48: =IFERROR(E48/C48-1,"") -> -0.1804211 | J48: 1.0179829e+08 | K48: 64253469 | L48: 46903609 | M48: 55936401 | N48: =IFERROR(K48/J48-1,"") -> -0.36881584 | O48: =IFERROR(L48/K48-1,"") -> -0.27002215 | P48: =IFERROR(M48/L48-1,"") -> 0.19258204 | Q48: =IFERROR(M48/K48-1,"") -> -0.12944153 | R48: 36343788 | S48: 23321133 | T48: 18351033 | U48: 24679206 | V48: =IFERROR(S48/R48-1,"") -> -0.35831858 | W48: =IFERROR(T48/S48-1,"") -> -0.21311575 | X48: =IFERROR(U48/T48-1,"") -> 0.34484019 | Y48: =IFERROR(U48/S48-1,"") -> 0.058233567
A49: СТУЛЬЯ ПОСЕТИТЕЛЬСКИЕ | B49: 107526 | C49: 64256 | D49: 58364 | E49: 67148 | F49: =IFERROR(C49/B49-1,"") -> -0.4024143 | G49: =IFERROR(D49/C49-1,"") -> -0.091695717 | H49: =IFERROR(E49/D49-1,"") -> 0.15050374 | I49: =IFERROR(E49/C49-1,"") -> 0.04500747 | J49: 77193435 | K49: 51648131 | L49: 46674389 | M49: 54214244 | N49: =IFERROR(K49/J49-1,"") -> -0.33092587 | O49: =IFERROR(L49/K49-1,"") -> -0.096300531 | P49: =IFERROR(M49/L49-1,"") -> 0.16154161 | Q49: =IFERROR(M49/K49-1,"") -> 0.049684536 | R49: 33002287 | S49: 22045621 | T49: 19928779 | U49: 25520626 | V49: =IFERROR(S49/R49-1,"") -> -0.33199717 | W49: =IFERROR(T49/S49-1,"") -> -0.096020966 | X49: =IFERROR(U49/T49-1,"") -> 0.28059152 | Y49: =IFERROR(U49/S49-1,"") -> 0.15762789
A50: КРЕСЛА/СТУЛЬЯ ОБЕДЕННЫЕ | B50: 78009 | C50: 58965 | D50: 40156 | E50: 47534 | F50: =IFERROR(C50/B50-1,"") -> -0.24412568 | G50: =IFERROR(D50/C50-1,"") -> -0.31898584 | H50: =IFERROR(E50/D50-1,"") -> 0.18373344 | I50: =IFERROR(E50/C50-1,"") -> -0.19386076 | J50: 66683260 | K50: 49237455 | L50: 27945548 | M50: 43255800 | N50: =IFERROR(K50/J50-1,"") -> -0.26162195 | O50: =IFERROR(L50/K50-1,"") -> -0.43243313 | P50: =IFERROR(M50/L50-1,"") -> 0.54786015 | Q50: =IFERROR(M50/K50-1,"") -> -0.12148586 | R50: 24715841 | S50: 17502361 | T50: 10575011 | U50: 19039783 | V50: =IFERROR(S50/R50-1,"") -> -0.29185657 | W50: =IFERROR(T50/S50-1,"") -> -0.39579513 | X50: =IFERROR(U50/T50-1,"") -> 0.80045037 | Y50: =IFERROR(U50/S50-1,"") -> 0.087840878
A51: СТОЛЫ ОБЕДЕННЫЕ | B51: 6808 | C51: 7086 | D51: 1539 | E51: 5029 | F51: =IFERROR(C51/B51-1,"") -> 0.040834313 | G51: =IFERROR(D51/C51-1,"") -> -0.78281118 | H51: =IFERROR(E51/D51-1,"") -> 2.2677063 | I51: =IFERROR(E51/C51-1,"") -> -0.29029071 | J51: 13274969 | K51: 14856408 | L51: 3462301.8 | M51: 11801728 | N51: =IFERROR(K51/J51-1,"") -> 0.11912935 | O51: =IFERROR(L51/K51-1,"") -> -0.76694892 | P51: =IFERROR(M51/L51-1,"") -> 2.4086365 | Q51: =IFERROR(M51/K51-1,"") -> -0.20561359 | R51: 4245578 | S51: 4785922.3 | T51: 1236084.8 | U51: 5069490 | V51: =IFERROR(S51/R51-1,"") -> 0.12727227 | W51: =IFERROR(T51/S51-1,"") -> -0.74172485 | X51: =IFERROR(U51/T51-1,"") -> 3.1012477 | Y51: =IFERROR(U51/S51-1,"") -> 0.059250361
A52: МЕБЕЛЬ КОРПУСНАЯ | B52: 3932.5 | C52: 2361 | D52: 1622 | E52: 1498 | F52: =IFERROR(C52/B52-1,"") -> -0.39961856 | G52: =IFERROR(D52/C52-1,"") -> -0.31300296 | H52: =IFERROR(E52/D52-1,"") -> -0.076448829 | I52: =IFERROR(E52/C52-1,"") -> -0.36552308 | J52: 10065870 | K52: 5679902 | L52: 4934825.8 | M52: 4877919.2 | N52: =IFERROR(K52/J52-1,"") -> -0.43572666 | O52: =IFERROR(L52/K52-1,"") -> -0.13117765 | P52: =IFERROR(M52/L52-1,"") -> -0.011531623 | Q52: =IFERROR(M52/K52-1,"") -> -0.14119658 | R52: 4222096.4 | S52: 2198456.6 | T52: 2256819.9 | U52: 1975349.1 | V52: =IFERROR(S52/R52-1,"") -> -0.4792974 | W52: =IFERROR(T52/S52-1,"") -> 0.026547401 | X52: =IFERROR(U52/T52-1,"") -> -0.1247201 | Y52: =IFERROR(U52/S52-1,"") -> -0.10148369
A53: КРЕСЛА ДЕТСКИЕ | B53: 8503 | C53: 3416 | D53: 3012 | E53: 2295 | F53: =IFERROR(C53/B53-1,"") -> -0.59825944 | G53: =IFERROR(D53/C53-1,"") -> -0.11826698 | H53: =IFERROR(E53/D53-1,"") -> -0.23804781 | I53: =IFERROR(E53/C53-1,"") -> -0.32816159 | J53: 14549396 | K53: 6480186.7 | L53: 4671519.1 | M53: 4709913.3 | N53: =IFERROR(K53/J53-1,"") -> -0.55460786 | O53: =IFERROR(L53/K53-1,"") -> -0.27910733 | P53: =IFERROR(M53/L53-1,"") -> 0.0082187841 | Q53: =IFERROR(M53/K53-1,"") -> -0.27318247 | R53: 5928440.8 | S53: 2412246.8 | T53: 1930051.5 | U53: 2236567.4 | V53: =IFERROR(S53/R53-1,"") -> -0.59310603 | W53: =IFERROR(T53/S53-1,"") -> -0.19989468 | X53: =IFERROR(U53/T53-1,"") -> 0.15881226 | Y53: =IFERROR(U53/S53-1,"") -> -0.072828138
A54: ШКОЛЬНАЯ МЕБЕЛЬ | B54: 4475 | C54: 1917 | D54: 12977 | E54: 3475 | F54: =IFERROR(C54/B54-1,"") -> -0.57162011 | G54: =IFERROR(D54/C54-1,"") -> 5.7694314 | H54: =IFERROR(E54/D54-1,"") -> -0.73221854 | I54: =IFERROR(E54/C54-1,"") -> 0.81272822 | J54: 4239927.1 | K54: 1956771.5 | L54: 11816811 | M54: 3111446.5 | N54: =IFERROR(K54/J54-1,"") -> -0.53848937 | O54: =IFERROR(L54/K54-1,"") -> 5.0389327 | P54: =IFERROR(M54/L54-1,"") -> -0.73669322 | Q54: =IFERROR(M54/K54-1,"") -> 0.5900919 | R54: 1910384.6 | S54: 842104.97 | T54: 3649948.1 | U54: 1181067.2 | V54: =IFERROR(S54/R54-1,"") -> -0.55919611 | W54: =IFERROR(T54/S54-1,"") -> 3.3343149 | X54: =IFERROR(U54/T54-1,"") -> -0.67641535 | Y54: =IFERROR(U54/S54-1,"") -> 0.40251777
A55: КРЕСЛА И СТУЛЬЯ СПЕЦИАЛЬНЫЕ | B55: 2133 | C55: 1664 | D55: 1467 | E55: 1156 | F55: =IFERROR(C55/B55-1,"") -> -0.21987811 | G55: =IFERROR(D55/C55-1,"") -> -0.11838942 | H55: =IFERROR(E55/D55-1,"") -> -0.21199727 | I55: =IFERROR(E55/C55-1,"") -> -0.30528846 | J55: 3900269.6 | K55: 3364475.8 | L55: 3463375.8 | M55: 2953696 | N55: =IFERROR(K55/J55-1,"") -> -0.13737353 | O55: =IFERROR(L55/K55-1,"") -> 0.029395364 | P55: =IFERROR(M55/L55-1,"") -> -0.14716272 | Q55: =IFERROR(M55/K55-1,"") -> -0.12209325 | R55: 1710718.3 | S55: 1421269.6 | T55: 1324346 | U55: 1271305.7 | V55: =IFERROR(S55/R55-1,"") -> -0.16919717 | W55: =IFERROR(T55/S55-1,"") -> -0.068195105 | X55: =IFERROR(U55/T55-1,"") -> -0.040050189 | Y55: =IFERROR(U55/S55-1,"") -> -0.10551407
A56: КОМПЛЕКТУЮЩИЕ СТОЛОВ, КРЕСЕЛ И СТУЛЬЕВ ОБЕДЕННЫХ | B56: 15093 | C56: 9342 | D56: 6957 | E56: 7040 | F56: =IFERROR(C56/B56-1,"") -> -0.38103757 | G56: =IFERROR(D56/C56-1,"") -> -0.25529865 | H56: =IFERROR(E56/D56-1,"") -> 0.01193043 | I56: =IFERROR(E56/C56-1,"") -> -0.24641404 | J56: 5550667.4 | K56: 3071901.3 | L56: 2897245.4 | M56: 2445725 | N56: =IFERROR(K56/J56-1,"") -> -0.44657083 | O56: =IFERROR(L56/K56-1,"") -> -0.056855965 | P56: =IFERROR(M56/L56-1,"") -> -0.15584472 | Q56: =IFERROR(M56/K56-1,"") -> -0.20383998 | R56: 2409463.1 | S56: 1294452.3 | T56: 1293366.7 | U56: 1171741.6 | V56: =IFERROR(S56/R56-1,"") -> -0.46276318 | W56: =IFERROR(T56/S56-1,"") -> -0.00083867503 | X56: =IFERROR(U56/T56-1,"") -> -0.094037611 | Y56: =IFERROR(U56/S56-1,"") -> -0.094797419
A57: СТУЛЬЯ БАРНЫЕ | B57: 1764 | C57: 1714 | D57: 689 | E57: 1201 | F57: =IFERROR(C57/B57-1,"") -> -0.028344671 | G57: =IFERROR(D57/C57-1,"") -> -0.59801634 | H57: =IFERROR(E57/D57-1,"") -> 0.74310595 | I57: =IFERROR(E57/C57-1,"") -> -0.29929988 | J57: 3099852.1 | K57: 3128273.7 | L57: 1220087.1 | M57: 2434195.9 | N57: =IFERROR(K57/J57-1,"") -> 0.0091686728 | O57: =IFERROR(L57/K57-1,"") -> -0.6099807 | P57: =IFERROR(M57/L57-1,"") -> 0.99510007 | Q57: =IFERROR(M57/K57-1,"") -> -0.22187247 | R57: 1175832.6 | S57: 1174931.8 | T57: 526905.54 | U57: 1086764 | V57: =IFERROR(S57/R57-1,"") -> -0.00076616556 | W57: =IFERROR(T57/S57-1,"") -> -0.55154371 | X57: =IFERROR(U57/T57-1,"") -> 1.0625404 | Y57: =IFERROR(U57/S57-1,"") -> -0.07504076
A58: МЯГКАЯ МЕБЕЛЬ | B58: 444 | C58: 570 | D58: 630 | E58: 431 | F58: =IFERROR(C58/B58-1,"") -> 0.28378378 | G58: =IFERROR(D58/C58-1,"") -> 0.10526316 | H58: =IFERROR(E58/D58-1,"") -> -0.31587302 | I58: =IFERROR(E58/C58-1,"") -> -0.24385965 | J58: 2405433.6 | K58: 2617486.3 | L58: 2979997.7 | M58: 2066375.7 | N58: =IFERROR(K58/J58-1,"") -> 0.08815572 | O58: =IFERROR(L58/K58-1,"") -> 0.13849599 | P58: =IFERROR(M58/L58-1,"") -> -0.3065848 | Q58: =IFERROR(M58/K58-1,"") -> -0.21054958 | R58: 1086348.6 | S58: 892745.76 | T58: 1199134.5 | U58: 881718.07 | V58: =IFERROR(S58/R58-1,"") -> -0.17821428 | W58: =IFERROR(T58/S58-1,"") -> 0.34319824 | X58: =IFERROR(U58/T58-1,"") -> -0.26470463 | Y58: =IFERROR(U58/S58-1,"") -> -0.012352554
... A62: Общий итог | B62: 315257.5 | C62: 204938 | D62: 164270 | E62: 181722 | F62: =IFERROR(C62/B62-1,"") -> -0.34993458 | G62: =IFERROR(D62/C62-1,"") -> -0.1984405 | H62: =IFERROR(E62/D62-1,"") -> 0.10623973 | I62: =IFERROR(E62/C62-1,"") -> -0.11328304 | J62: 4.1703718e+08 | K62: 2.9029148e+08 | L62: 2.1029576e+08 | M62: 2.7197929e+08 | N62: =IFERROR(K62/J62-1,"") -> -0.30391941 | O62: =IFERROR(L62/K62-1,"") -> -0.27557035 | P62: =IFERROR(M62/L62-1,"") -> 0.29331799 | Q62: =IFERROR(M62/K62-1,"") -> -0.063082097 | R62: 1.6188722e+08 | S62: 1.0957985e+08 | T62: 84557444 | U62: 1.2280211e+08 | V62: =IFERROR(S62/R62-1,"") -> -0.32310996 | W62: =IFERROR(T62/S62-1,"") -> -0.22834858 | X62: =IFERROR(U62/T62-1,"") -> 0.45229209 | Y62: =IFERROR(U62/S62-1,"") -> 0.12066326
A63: Общий итог, млн. грн. | B63: 315257.5 | C63: 204938 | D63: 164270 | E63: 181722 | F63: =IFERROR(C63/B63-1,"") -> -0.34993458 | G63: =IFERROR(D63/C63-1,"") -> -0.1984405 | H63: =IFERROR(E63/D63-1,"") -> 0.10623973 | I63: =IFERROR(E63/C63-1,"") -> -0.11328304 | J63: =MROUND(J62/1000000,1) -> 417 | K63: =MROUND(K62/1000000,1) -> 290 | L63: =MROUND(L62/1000000,1) -> 210 | M63: =MROUND(M62/1000000,1) -> 272 | N63: =IFERROR(K63/J63-1,"") -> -0.30455635 | O63: =IFERROR(L63/K63-1,"") -> -0.27586207 | P63: =IFERROR(M63/L63-1,"") -> 0.2952381 | Q63: =IFERROR(M63/K63-1,"") -> -0.062068966 | R63: =MROUND(R62/1000000,1) -> 162 | S63: =MROUND(S62/1000000,1) -> 110 | T63: =MROUND(T62/1000000,1) -> 85 | U63: =MROUND(U62/1000000,1) -> 123 | V63: =IFERROR(S63/R63-1,"") -> -0.32098765 | W63: =IFERROR(T63/S63-1,"") -> -0.22727273 | X63: =IFERROR(U63/T63-1,"") -> 0.44705882 | Y63: =IFERROR(U63/S63-1,"") -> 0.11818182

Sheet Тренды категорий
A1: Категория | B1: Доход за июль-декабрь 2023, грн. | C1: Доход за январь - июнь 2024, грн. | D1: Доход за июль-декабрь 2024, грн. | E1: Доход за январь - июнь 2025, грн | F1: 01-06.2024 к 07-12.2023 | G1: 07-12.2024 к 01-06.2024 | H1: 01-06.2025 к 07-12.2024 | I1: Изменение 01-06.2025 к 01-06.2024
A2: КРЕСЛА РУКОВОДИТЕЛЯ | B2: 1.0435148e+08 | C2: 76149864 | D2: 48903591 | E2: 80667045 | F2: =IFERROR(C2/B2-1,"") -> -0.27025604 | G2: =IFERROR(D2/C2-1,"") -> -0.35779805 | H2: =IFERROR(E2/D2-1,"") -> 0.64951169 | I2: =IFERROR(E2/C2-1,"") -> 0.059319619
A3: КРЕСЛА ОПЕРАТОРСКИЕ | B3: 1.0179829e+08 | C3: 64253469 | D3: 46903609 | E3: 55936401 | F3: =IFERROR(C3/B3-1,"") -> -0.36881584 | G3: =IFERROR(D3/C3-1,"") -> -0.27002215 | H3: =IFERROR(E3/D3-1,"") -> 0.19258204 | I3: =IFERROR(E3/C3-1,"") -> -0.12944153
A4: СТУЛЬЯ ПОСЕТИТЕЛЬСКИЕ | B4: 77193435 | C4: 51648131 | D4: 46674389 | E4: 54214244 | F4: =IFERROR(C4/B4-1,"") -> -0.33092587 | G4: =IFERROR(D4/C4-1,"") -> -0.096300531 | H4: =IFERROR(E4/D4-1,"") -> 0.16154161 | I4: =IFERROR(E4/C4-1,"") -> 0.049684536
A5: КРЕСЛА/СТУЛЬЯ ОБЕДЕННЫЕ | B5: 66683260 | C5: 49237455 | D5: 27945548 | E5: 43255800 | F5: =IFERROR(C5/B5-1,"") -> -0.26162195 | G5: =IFERROR(D5/C5-1,"") -> -0.43243313 | H5: =IFERROR(E5/D5-1,"") -> 0.54786015 | I5: =IFERROR(E5/C5-1,"") -> -0.12148586
A6: СТОЛЫ ОБЕДЕННЫЕ | B6: 13274969 | C6: 14856408 | D6: 3462301.8 | E6: 11801728 | F6: =IFERROR(C6/B6-1,"") -> 0.11912935 | G6: =IFERROR(D6/C6-1,"") -> -0.76694892 | H6: =IFERROR(E6/D6-1,"") -> 2.4086365 | I6: =IFERROR(E6/C6-1,"") -> -0.20561359 | Y6: За счет столов Modern, argon, aqua, talio, calipso, casey
A7: МЕБЕЛЬ КОРПУСНАЯ | B7: 10065870 | C7: 5679902 | D7: 4934825.8 | E7: 4877919.2 | F7: =IFERROR(C7/B7-1,"") -> -0.43572666 | G7: =IFERROR(D7/C7-1,"") -> -0.13117765 | H7: =IFERROR(E7/D7-1,"") -> -0.011531623 | I7: =IFERROR(E7/C7-1,"") -> -0.14119658
A8: КРЕСЛА ДЕТСКИЕ | B8: 14549396 | C8: 6480186.7 | D8: 4671519.1 | E8: 4709913.3 | F8: =IFERROR(C8/B8-1,"") -> -0.55460786 | G8: =IFERROR(D8/C8-1,"") -> -0.27910733 | H8: =IFERROR(E8/D8-1,"") -> 0.0082187841 | I8: =IFERROR(E8/C8-1,"") -> -0.27318247
A9: ШКОЛЬНАЯ МЕБЕЛЬ | B9: 4239927.1 | C9: 1956771.5 | D9: 11816811 | E9: 3111446.5 | F9: =IFERROR(C9/B9-1,"") -> -0.53848937 | G9: =IFERROR(D9/C9-1,"") -> 5.0389327 | H9: =IFERROR(E9/D9-1,"") -> -0.73669322 | I9: =IFERROR(E9/C9-1,"") -> 0.5900919 | Y9: За счет стола 176 и стула и стула 279 в октябре
A10: КРЕСЛА И СТУЛЬЯ СПЕЦИАЛЬНЫЕ | B10: 3900269.6 | C10: 3364475.8 | D10: 3463375.8 | E10: 2953696 | F10: =IFERROR(C10/B10-1,"") -> -0.13737353 | G10: =IFERROR(D10/C10-1,"") -> 0.029395364 | H10: =IFERROR(E10/D10-1,"") -> -0.14716272 | I10: =IFERROR(E10/C10-1,"") -> -0.12209325
A11: КОМПЛЕКТУЮЩИЕ СТОЛОВ, КРЕСЕЛ И СТУЛЬЕВ ОБЕДЕННЫХ | B11: 5550667.4 | C11: 3071901.3 | D11: 2897245.4 | E11: 2445725 | F11: =IFERROR(C11/B11-1,"") -> -0.44657083 | G11: =IFERROR(D11/C11-1,"") -> -0.056855965 | H11: =IFERROR(E11/D11-1,"") -> -0.15584472 | I11: =IFERROR(E11/C11-1,"") -> -0.20383998
A12: СТУЛЬЯ БАРНЫЕ | B12: 3099852.1 | C12: 3128273.7 | D12: 1220087.1 | E12: 2434195.9 | F12: =IFERROR(C12/B12-1,"") -> 0.0091686728 | G12: =IFERROR(D12/C12-1,"") -> -0.6099807 | H12: =IFERROR(E12/D12-1,"") -> 0.99510007 | I12: =IFERROR(E12/C12-1,"") -> -0.22187247
A13: МЯГКАЯ МЕБЕЛЬ | B13: 2405433.6 | C13: 2617486.3 | D13: 2979997.7 | E13: 2066375.7 | F13: =IFERROR(C13/B13-1,"") -> 0.08815572 | G13: =IFERROR(D13/C13-1,"") -> 0.13849599 | H13: =IFERROR(E13/D13-1,"") -> -0.3065848 | I13: =IFERROR(E13/C13-1,"") -> -0.21054958
A14: КРЕСЛА ГЕЙМЕРСКИЕ | B14: 5191399 | C14: 5461875.9 | D14: 2641522.1 | E14: 1957770.3 | F14: =IFERROR(C14/B14-1,"") -> 0.052100957 | G14: =IFERROR(D14/C14-1,"") -> -0.5163709 | H14: =IFERROR(E14/D14-1,"") -> -0.25884767 | I14: =IFERROR(E14/C14-1,"") -> -0.64155716
A15: ВЕШАЛКИ НАПОЛЬНЫЕ | B15: 4732923.6 | C15: 2385283.9 | D15: 1569499.1 | E15: 1506205.4 | F15: =IFERROR(C15/B15-1,"") -> -0.49602316 | G15: =IFERROR(D15/C15-1,"") -> -0.34200743 | H15: =IFERROR(E15/D15-1,"") -> -0.04032729 | I15: =IFERROR(E15/C15-1,"") -> -0.36854249
A16: КРОВАТИ И МАТРАСЫ | B16: 0 | C16: 0 | D16: 211437.15 | E16: 40821.2 | F16: =IFERROR(C16/B16-1,"") | G16: =IFERROR(D16/C16-1,"") | H16: =IFERROR(E16/D16-1,"") -> -0.80693459 | I16: =IFERROR(E16/C16-1,"")
A17: Общий итог | B17: 4.1703718e+08 | C17: 2.9029148e+08 | D17: 2.1029576e+08 | E17: 2.7197929e+08 | F17: =IFERROR(C17/B17-1,"") -> -0.30391941 | G17: =IFERROR(D17/C17-1,"") -> -0.27557035 | H17: =IFERROR(E17/D17-1,"") -> 0.29331799 | I17: =IFERROR(E17/C17-1,"") -> -0.063082097
A20: Категория | B20: Маржа за июль-декабрь 2023, грн. | C20: Маржа за январь - июнь 2024, грн. | D20: Маржа за июль-декабрь 2024, грн. | E20: Маржа за январь - июнь 2025, грн | F20: Изменение 01-06.2024 к 07-12.2023 | G20: Изменение 07-12.2024 к 01-06.2024 | H20: Изменение 01-06.2025 к 07-12.2024 | I20: Изменение 01-06.2025 к 01-06.2024 | J20: Продажи за июль-декабрь 2023, шт | K20: Продажи за январь - июнь 2024, шт | L20: Продажи за июль-декабрь 2024, шт. | M20: Продажи за январь - июнь 2025, шт | N20: Изменение 01-06.2024 к 07-12.2023 | O20: Изменение 07-12.2024 к 01-06.2024 | P20: Изменение 01-06.2025 к 07-12.2024 | Q20: Изменение 01-06.2025 к 01-06.2024
A21: КРЕСЛА РУКОВОДИТЕЛЯ | B21: 41678917 | C21: 29293819 | D21: 20819003 | E21: 37262622 | F21: =IFERROR(C21/B21-1,"") -> -0.29715499 | G21: =IFERROR(D21/C21-1,"") -> -0.28930389 | H21: =IFERROR(E21/D21-1,"") -> 0.78983703 | I21: =IFERROR(E21/C21-1,"") -> 0.2720302 | J21: 26725 | K21: 19187 | L21: 11862 | M21: 17643 | N21: =IFERROR(K21/J21-1,"") -> -0.282058 | O21: =IFERROR(L21/K21-1,"") -> -0.38176891 | P21: =IFERROR(M21/L21-1,"") -> 0.48735458 | Q21: =IFERROR(M21/K21-1,"") -> -0.080471152
A22: КРЕСЛА ОПЕРАТОРСКИЕ | B22: 36343788 | C22: 23321133 | D22: 18351033 | E22: 24679206 | F22: =IFERROR(C22/B22-1,"") -> -0.35831858 | G22: =IFERROR(D22/C22-1,"") -> -0.21311575 | H22: =IFERROR(E22/D22-1,"") -> 0.34484019 | I22: =IFERROR(E22/C22-1,"") -> 0.058233567 | J22: 54881 | K22: 31299 | L22: 22967 | M22: 25652 | N22: =IFERROR(K22/J22-1,"") -> -0.42969334 | O22: =IFERROR(L22/K22-1,"") -> -0.26620659 | P22: =IFERROR(M22/L22-1,"") -> 0.11690687 | Q22: =IFERROR(M22/K22-1,"") -> -0.1804211
A23: СТУЛЬЯ ПОСЕТИТЕЛЬСКИЕ | B23: 33002287 | C23: 22045621 | D23: 19928779 | E23: 25520626 | F23: =IFERROR(C23/B23-1,"") -> -0.33199717 | G23: =IFERROR(D23/C23-1,"") -> -0.096020966 | H23: =IFERROR(E23/D23-1,"") -> 0.28059152 | I23: =IFERROR(E23/C23-1,"") -> 0.15762789 | J23: 107526 | K23: 64256 | L23: 58364 | M23: 67148 | N23: =IFERROR(K23/J23-1,"") -> -0.4024143 | O23: =IFERROR(L23/K23-1,"") -> -0.091695717 | P23: =IFERROR(M23/L23-1,"") -> 0.15050374 | Q23: =IFERROR(M23/K23-1,"") -> 0.04500747
A24: КРЕСЛА/СТУЛЬЯ ОБЕДЕННЫЕ | B24: 24715841 | C24: 17502361 | D24: 10575011 | E24: 19039783 | F24: =IFERROR(C24/B24-1,"") -> -0.29185657 | G24: =IFERROR(D24/C24-1,"") -> -0.39579513 | H24: =IFERROR(E24/D24-1,"") -> 0.80045037 | I24: =IFERROR(E24/C24-1,"") -> 0.087840878 | J24: 78009 | K24: 58965 | L24: 40156 | M24: 47534 | N24: =IFERROR(K24/J24-1,"") -> -0.24412568 | O24: =IFERROR(L24/K24-1,"") -> -0.31898584 | P24: =IFERROR(M24/L24-1,"") -> 0.18373344 | Q24: =IFERROR(M24/K24-1,"") -> -0.19386076
A25: СТОЛЫ ОБЕДЕННЫЕ | B25: 4245578 | C25: 4785922.3 | D25: 1236084.8 | E25: 5069490 | F25: =IFERROR(C25/B25-1,"") -> 0.12727227 | G25: =IFERROR(D25/C25-1,"") -> -0.74172485 | H25: =IFERROR(E25/D25-1,"") -> 3.1012477 | I25: =IFERROR(E25/C25-1,"") -> 0.059250361 | J25: 6808 | K25: 7086 | L25: 1539 | M25: 5029 | N25: =IFERROR(K25/J25-1,"") -> 0.040834313 | O25: =IFERROR(L25/K25-1,"") -> -0.78281118 | P25: =IFERROR(M25/L25-1,"") -> 2.2677063 | Q25: =IFERROR(M25/K25-1,"") -> -0.29029071 | Y25: За счет столов Modern, argon, aqua, talio, calipso, casey
A26: МЕБЕЛЬ КОРПУСНАЯ | B26: 4222096.4 | C26: 2198456.6 | D26: 2256819.9 | E26: 1975349.1 | F26: =IFERROR(C26/B26-1,"") -> -0.4792974 | G26: =IFERROR(D26/C26-1,"") -> 0.026547401 | H26: =IFERROR(E26/D26-1,"") -> -0.1247201 | I26: =IFERROR(E26/C26-1,"") -> -0.10148369 | J26: 3932.5 | K26: 2361 | L26: 1622 | M26: 1498 | N26: =IFERROR(K26/J26-1,"") -> -0.39961856 | O26: =IFERROR(L26/K26-1,"") -> -0.31300296 | P26: =IFERROR(M26/L26-1,"") -> -0.076448829 | Q26: =IFERROR(M26/K26-1,"") -> -0.36552308
A27: КРЕСЛА ДЕТСКИЕ | B27: 5928440.8 | C27: 2412246.8 | D27: 1930051.5 | E27: 2236567.4 | F27: =IFERROR(C27/B27-1,"") -> -0.59310603 | G27: =IFERROR(D27/C27-1,"") -> -0.19989468 | H27: =IFERROR(E27/D27-1,"") -> 0.15881226 | I27: =IFERROR(E27/C27-1,"") -> -0.072828138 | J27: 8503 | K27: 3416 | L27: 3012 | M27: 2295 | N27: =IFERROR(K27/J27-1,"") -> -0.59825944 | O27: =IFERROR(L27/K27-1,"") -> -0.11826698 | P27: =IFERROR(M27/L27-1,"") -> -0.23804781 | Q27: =IFERROR(M27/K27-1,"") -> -0.32816159
A28: ШКОЛЬНАЯ МЕБЕЛЬ | B28: 1910384.6 | C28: 842104.97 | D28: 3649948.1 | E28: 1181067.2 | F28: =IFERROR(C28/B28-1,"") -> -0.55919611 | G28: =IFERROR(D28/C28-1,"") -> 3.3343149 | H28: =IFERROR(E28/D28-1,"") -> -0.67641535 | I28: =IFERROR(E28/C28-1,"") -> 0.40251777 | J28: 4475 | K28: 1917 | L28: 12977 | M28: 3475 | N28: =IFERROR(K28/J28-1,"") -> -0.57162011 | O28: =IFERROR(L28/K28-1,"") -> 5.7694314 | P28: =IFERROR(M28/L28-1,"") -> -0.73221854 | Q28: =IFERROR(M28/K28-1,"") -> 0.81272822 | Y28: За счет стола 176 и стула и стула 279 в октябре
A29: КРЕСЛА И СТУЛЬЯ СПЕЦИАЛЬНЫЕ | B29: 1710718.3 | C29: 1421269.6 | D29: 1324346 | E29: 1271305.7 | F29: =IFERROR(C29/B29-1,"") -> -0.16919717 | G29: =IFERROR(D29/C29-1,"") -> -0.068195105 | H29: =IFERROR(E29/D29-1,"") -> -0.040050189 | I29: =IFERROR(E29/C29-1,"") -> -0.10551407 | J29: 2133 | K29: 1664 | L29: 1467 | M29: 1156 | N29: =IFERROR(K29/J29-1,"") -> -0.21987811 | O29: =IFERROR(L29/K29-1,"") -> -0.11838942 | P29: =IFERROR(M29/L29-1,"") -> -0.21199727 | Q29: =IFERROR(M29/K29-1,"") -> -0.30528846
A30: КОМПЛЕКТУЮЩИЕ СТОЛОВ, КРЕСЕЛ И СТУЛЬЕВ ОБЕДЕННЫХ | B30: 2409463.1 | C30: 1294452.3 | D30: 1293366.7 | E30: 1171741.6 | F30: =IFERROR(C30/B30-1,"") -> -0.46276318 | G30: =IFERROR(D30/C30-1,"") -> -0.00083867503 | H30: =IFERROR(E30/D30-1,"") -> -0.094037611 | I30: =IFERROR(E30/C30-1,"") -> -0.094797419 | J30: 15093 | K30: 9342 | L30: 6957 | M30: 7040 | N30: =IFERROR(K30/J30-1,"") -> -0.38103757 | O30: =IFERROR(L30/K30-1,"") -> -0.25529865 | P30: =IFERROR(M30/L30-1,"") -> 0.01193043 | Q30: =IFERROR(M30/K30-1,"") -> -0.24641404
A31: СТУЛЬЯ БАРНЫЕ | B31: 1175832.6 | C31: 1174931.8 | D31: 526905.54 | E31: 1086764 | F31: =IFERROR(C31/B31-1,"") -> -0.00076616556 | G31: =IFERROR(D31/C31-1,"") -> -0.55154371 | H31: =IFERROR(E31/D31-1,"") -> 1.0625404 | I31: =IFERROR(E31/C31-1,"") -> -0.07504076 | J31: 1764 | K31: 1714 | L31: 689 | M31: 1201 | N31: =IFERROR(K31/J31-1,"") -> -0.028344671 | O31: =IFERROR(L31/K31-1,"") -> -0.59801634 | P31: =IFERROR(M31/L31-1,"") -> 0.74310595 | Q31: =IFERROR(M31/K31-1,"") -> -0.29929988
A32: МЯГКАЯ МЕБЕЛЬ | B32: 1086348.6 | C32: 892745.76 | D32: 1199134.5 | E32: 881718.07 | F32: =IFERROR(C32/B32-1,"") -> -0.17821428 | G32: =IFERROR(D32/C32-1,"") -> 0.34319824 | H32: =IFERROR(E32/D32-1,"") -> -0.26470463 | I32: =IFERROR(E32/C32-1,"") -> -0.012352554 | J32: 444 | K32: 570 | L32: 630 | M32: 431 | N32: =IFERROR(K32/J32-1,"") -> 0.28378378 | O32: =IFERROR(L32/K32-1,"") -> 0.10526316 | P32: =IFERROR(M32/L32-1,"") -> -0.31587302 | Q32: =IFERROR(M32/K32-1,"") -> -0.24385965
A33: КРЕСЛА ГЕЙМЕРСКИЕ | B33: 1407241.6 | C33: 1342205.9 | D33: 671537.06 | E33: 687505.3 | F33: =IFERROR(C33/B33-1,"") -> -0.046215006 | G33: =IFERROR(D33/C33-1,"") -> -0.49967657 | H33: =IFERROR(E33/D33-1,"") -> 0.023778637 | I33: =IFERROR(E33/C33-1,"") -> -0.48777956 | J33: 1147 | K33: 1090 | L33: 544 | M33: 366 | N33: =IFERROR(K33/J33-1,"") -> -0.049694856 | O33: =IFERROR(L33/K33-1,"") -> -0.50091743 | P33: =IFERROR(M33/L33-1,"") -> -0.32720588 | Q33: =IFERROR(M33/K33-1,"") -> -0.66422018
A34: ВЕШАЛКИ НАПОЛЬНЫЕ | B34: 2050281.2 | C34: 1052575.6 | D34: 731319.49 | E34: 724816.76 | F34: =IFERROR(C34/B34-1,"") -> -0.48661892 | G34: =IFERROR(D34/C34-1,"") -> -0.30520951 | H34: =IFERROR(E34/D34-1,"") -> -0.0088917767 | I34: =IFERROR(E34/C34-1,"") -> -0.31138744 | J34: 3817 | K34: 2071 | L34: 1405 | M34: 1243 | N34: =IFERROR(K34/J34-1,"") -> -0.4574273 | O34: =IFERROR(L34/K34-1,"") -> -0.32158378 | P34: =IFERROR(M34/L34-1,"") -> -0.11530249 | Q34: =IFERROR(M34/K34-1,"") -> -0.39980686
A35: КРОВАТИ И МАТРАСЫ | B35: 0 | C35: 0 | D35: 64103.814 | E35: 13544.468 | F35: =IFERROR(C35/B35-1,"") | G35: =IFERROR(D35/C35-1,"") | H35: =IFERROR(E35/D35-1,"") -> -0.78871042 | I35: =IFERROR(E35/C35-1,"") | J35: 0 | K35: 0 | L35: 79 | M35: 11 | N35: =IFERROR(K35/J35-1,"") | O35: =IFERROR(L35/K35-1,"") | P35: =IFERROR(M35/L35-1,"") -> -0.86075949 | Q35: =IFERROR(M35/K35-1,"")
A36: Общий итог | B36: 1.6188722e+08 | C36: 1.0957985e+08 | D36: 84557444 | E36: 1.2280211e+08 | F36: =IFERROR(C36/B36-1,"") -> -0.32310996 | G36: =IFERROR(D36/C36-1,"") -> -0.22834858 | H36: =IFERROR(E36/D36-1,"") -> 0.45229209 | I36: =IFERROR(E36/C36-1,"") -> 0.12066326 | J36: 315257.5 | K36: 204938 | L36: 164270 | M36: 181722 | N36: =IFERROR(K36/J36-1,"") -> -0.34993458 | O36: =IFERROR(L36/K36-1,"") -> -0.1984405 | P36: =IFERROR(M36/L36-1,"") -> 0.10623973 | Q36: =IFERROR(M36/K36-1,"") -> -0.11328304

Sheet BCG
AB1: 0 | AC1: Темная лошадка | AD1: пользуются спросом, но еще слабо представлены на рынке | AM1: рост доли в доходах выше предыдущего периода, а доля в доходах ниже медианы
AB2: 1 | AC2: Звезда | AD2: прибыльны и продолжают захватывать рынок | AM2: рост доли в доходах выше предыдущего периода, а доля в доходах выше медианы
F3: медиана | J3: медиана | P3: медиана | V3: медиана | AB3: 11 | AC3: Корова | AD3: теряют популярность, но приносят прибыль | AM3: рост доли в доходах ниже предыдущего периода, а доля в доходах выше медианы
B4: внести новое и удалить выведенные | F4: ='Факт продаж'!D24 -> 0.00078193108 | J4: ='Факт продаж'!M24 -> 0.00082965831 | P4: ='Факт продаж'!V24 -> 0.00093074691 | V4: ='Факт продаж'!AE24 -> 0.00084150915 | AB4: 10 | AC4: Собака | AD4: не интересны потребителю и плохо продаются | AJ4: Плюс GAMER | AM4: рост доли в доходах ниже предыдущего периода, а доля в доходах ниже медианы
A5: КАТЕГОРИЯ | B5: ЛИНИЯ МОДЕЛИ | C5: Продажи за октябрь - декабрь 2024 (IV кв 2024), шт | D5: Доход за октябрь - декабрь 2024 (IV кв 2024), грн. | E5: Маржа за октябрь - декабрь 2024 (IV кв 2024), грн. | F5: Доля в доходах за октябрь - декабрь 2024 (IV кв 2024) | G5: Продажи за апрель - июнь 2025 (II кв 2025), шт | H5: Доход за апрель - июнь 2025 (II кв 2025), грн. | I5: Маржа за апрель - июнь 2025 (II кв 2025), грн. | J5: Доля в доходах за апрель - июнь 2025 (II кв 2025) | K5: РОСТ доходах апрель - июнь 2025 (II кв 2025) | L5: РОСТ доли в доходах апрель - июнь 2025 (II кв 2025) | M5: Продажи за июль - сентябрь 2025 (III кв 2025), шт. | N5: Доход за июль - сентябрь 2025 (III кв 2025), грн. | O5: Маржа за июль - сентябрь 2025 (III кв 2025), грн. | P5: Доля в доходах за июль - сентябрь 2025 (III кв 2025) | Q5: РОСТ доходах июль - сентябрь 2025 (III кв 2025) | R5: РОСТ доли в доходах июль - сентябрь 2025 (III кв 2025) | S5: Продажи за октябрь - декабрь 2025 (IV кв 2025), шт | T5: Доход за октябрь - декабрь 2025 (IV кв 2025), грн | U5: Маржа за октябрь - декабрь 2025 (IV кв 2025), грн | V5: Доля в доходах за октябрь - декабрь 2025 (IV кв 2025) | W5: РОСТ доходах октябрь - декабрь 2025 (IV кв 2025) | X5: РОСТ доли в доходах октябрь - декабрь 2025 (IV кв 2025) | Y5: РОСТ доходов за IV кв 2025 к III кв 2025 | Z5: РОСТ доли доходов за IV кв 2025 кIV кв 2024 | AB5: Группа по BCG | AF5: ABC анализ | AJ5: =COUNTIF(AJ7:AJ1048566,"PROMO") -> 39 | AK5: =COUNTIF(AK7:AK1048566,"PROMO") -> 0 | AL5: Инфо
AB6: октябрь - декабрь 2024 (IV кв 2024) | AC6: апрель - июнь 2025 (II кв 2025) | AD6: июль - сентябрь 2025 (III кв 2025) | AE6: октябрь - декабрь 2025 (IV кв 2025) | AF6: (IV кв 2024) | AG6: (II кв 2025) | AH6: (III кв 2025) | AI6: (IV кв 2025) | AJ6: PROMO old | AK6: PROMO new
A7: ДИВАНЫ НЕРАСКЛАДНЫЕ, ПУФЫ | B7: N-JOY | C7: =IFERROR(VLOOKUP(B7,'Факт продаж'!A:B,2,0),"нет продаж") -> нет продаж | D7: =IFERROR(VLOOKUP(B7,'Факт продаж'!A:C,3,0),"нет продаж") -> нет продаж | E7: =IFERROR(VLOOKUP(B7,'Факт продаж'!A:E,5,0),"нет продаж") -> нет продаж | F7: =IFERROR(VLOOKUP(B7,'Факт продаж'!A:C,3,0)/SUM('План Антонова'!$C$11:$C$13),0) -> 0 | G7: =IFERROR(VLOOKUP(B7,'Факт продаж'!J:K,2,0),"нет продаж") -> 3 | H7: =IFERROR(VLOOKUP(B7,'Факт продаж'!J:L,3,0),"нет продаж") -> 6373.8 | I7: =IFERROR(VLOOKUP(B7,'Факт продаж'!J:N,5,0),"нет продаж") -> 2945.7462 | J7: =IFERROR(VLOOKUP(B7,'Факт продаж'!J:L,3,0)/SUM('План Антонова'!$C$14:$C$16),0) -> 4.4010198e-05 | K7: =IFERROR(VLOOKUP(B7,'Факт продаж'!J:O,6,0),"-") -> 1 | L7: =IF(AND(F7=0,J7>0),5,IF(J7/F7>5,5,IF(J7/F7=0,0.0000001,J7/F7))) -> 5 | M7: =IFERROR(VLOOKUP(B7,'Факт продаж'!S:T,2,0),"нет продаж") -> 1 | N7: =IFERROR(VLOOKUP(B7,'Факт продаж'!S:U,3,0),"нет продаж") -> 2345.3 | O7: =IFERROR(VLOOKUP(B7,'Факт продаж'!S:W,5,0),"нет продаж") -> 991.63304 | P7: =IFERROR(VLOOKUP(B7,'Факт продаж'!S:U,3,0)/SUM('План Антонова'!$C$17:$C$19),0) -> 1.428534e-05 | Q7: =IFERROR(VLOOKUP(B7,'Факт продаж'!S:X,6,0),"-") -> -0.66336779 | R7: =IF(AND(J7=0,P7>0),5,IF(P7/J7>5,5,IF(P7/J7=0,0.0000001,P7/J7))) -> 0.3245916 | S7: =IFERROR(VLOOKUP(B7,'Факт продаж'!AB:AD,2,0),"нет продаж") -> нет продаж | T7: =IFERROR(VLOOKUP(B7,'Факт продаж'!AB:AD,3,0),"нет продаж") -> нет продаж | U7: =IFERROR(VLOOKUP(B7,'Факт продаж'!AB:AF,5,0),"нет продаж") -> нет продаж | V7: =IFERROR(VLOOKUP(B7,'Факт продаж'!AB:AD,3,0)/SUM('План Антонова'!$C$20:$C$22),0) -> 0 | W7: =IFERROR(VLOOKUP(B7,'Факт продаж'!AB:AG,6,0),"-") -> - | X7: =IF(AND(P7=0,V7>0),5,IF(V7/P7>5,5,IF(V7/P7=0,0.0000001,V7/P7))) -> 1e-07 | Y7: =IFERROR(VLOOKUP(B7,'Факт продаж'!AB:AH,7,0),"-") -> - | Z7: =IF(AND(F7=0,V7>0),5,IF(V7/F7>5,5,IF(V7/F7=0,0.0000001,V7/F7))) -> #DIV/0! | AB7: =IFERROR(VLOOKUP(VALUE(IF(L7<1,1,0)&IF(J7<'Факт продаж'!$M$24,0,1)),$AB$1:$AC$4,2,FALSE),"НЕТ ПРОДАЖ") -> Темная лошадка | AC7: =IFERROR(VLOOKUP(VALUE(IF(R7<1,1,0)&IF(P7<'Факт продаж'!$V$24,0,1)),$AB$1:$AC$4,2,FALSE),"НЕТ ПРОДАЖ") -> Собака | AD7: =IFERROR(VLOOKUP(VALUE(IF(X7<1,1,0)&IF(V7<'Факт продаж'!$AE$24,0,1)),$AB$1:$AC$4,2,FALSE),"НЕТ ПРОДАЖ") -> Собака | AE7: =IFERROR(VLOOKUP(VALUE(IF(Z7<1,1,0)&IF(V7<'Факт продаж'!$AE$24,0,1)),$AB$1:$AC$4,2,FALSE),"НЕТ ПРОДАЖ") -> НЕТ ПРОДАЖ | AF7: =VLOOKUP(B7,'ABC расчет'!B:G,6,0) -> C | AG7: =VLOOKUP(B7,'ABC расчет'!K:P,6,0) -> C | AH7: =VLOOKUP(B7,'ABC расчет'!T:Y,6,0) -> C | AI7: =VLOOKUP(B7,'ABC расчет'!AC:AH,6,0) -> C
A8: КОМПЛЕКТУЮЩИЕ СТОЛОВ, КРЕСЕЛ И СТУЛЬЕВ ОБЕДЕННЫХ | B8: KAJA | C8: =IFERROR(VLOOKUP(B8,'Факт продаж'!A:B,2,0),"нет продаж") -> нет продаж | D8: =IFERROR(VLOOKUP(B8,'Факт продаж'!A:C,3,0),"нет продаж") -> нет продаж | E8: =IFERROR(VLOOKUP(B8,'Факт продаж'!A:E,5,0),"нет продаж") -> нет продаж | F8: =IFERROR(VLOOKUP(B8,'Факт продаж'!A:C,3,0)/SUM('План Антонова'!$C$11:$C$13),0) -> 0 | G8: =IFERROR(VLOOKUP(B8,'Факт продаж'!J:K,2,0),"нет продаж") -> 20 | H8: =IFERROR(VLOOKUP(B8,'Факт продаж'!J:L,3,0),"нет продаж") -> 20577.1 | I8: =IFERROR(VLOOKUP(B8,'Факт продаж'!J:N,5,0),"нет продаж") -> 12818.378 | J8: =IFERROR(VLOOKUP(B8,'Факт продаж'!J:L,3,0)/SUM('План Антонова'!$C$14:$C$16),0) -> 0.000142082 | K8: =IFERROR(VLOOKUP(B8,'Факт продаж'!J:O,6,0),"-") -> 1 | L8: =IF(AND(F8=0,J8>0),5,IF(J8/F8>5,5,IF(J8/F8=0,0.0000001,J8/F8))) -> 5 | M8: =IFERROR(VLOOKUP(B8,'Факт продаж'!S:T,2,0),"нет продаж") -> 7 | N8: =IFERROR(VLOOKUP(B8,'Факт продаж'!S:U,3,0),"нет продаж") -> 7042 | O8: =IFERROR(VLOOKUP(B8,'Факт продаж'!S:W,5,0),"нет продаж") -> 4047.5662 | P8: =IFERROR(VLOOKUP(B8,'Факт продаж'!S:U,3,0)/SUM('План Антонова'!$C$17:$C$19),0) -> 4.2893177e-05 | Q8: =IFERROR(VLOOKUP(B8,'Факт продаж'!S:X,6,0),"-") -> -0.68423726 | R8: =IF(AND(J8=0,P8>0),5,IF(P8/J8>5,5,IF(P8/J8=0,0.0000001,P8/J8))) -> 0.30189029 | S8: =IFERROR(VLOOKUP(B8,'Факт продаж'!AB:AD,2,0),"нет продаж") -> нет продаж | T8: =IFERROR(VLOOKUP(B8,'Факт продаж'!AB:AD,3,0),"нет продаж") -> нет продаж | U8: =IFERROR(VLOOKUP(B8,'Факт продаж'!AB:AF,5,0),"нет продаж") -> нет продаж | V8: =IFERROR(VLOOKUP(B8,'Факт продаж'!AB:AD,3,0)/SUM('План Антонова'!$C$20:$C$22),0) -> 0 | W8: =IFERROR(VLOOKUP(B8,'Факт продаж'!AB:AG,6,0),"-") -> - | X8: =IF(AND(P8=0,V8>0),5,IF(V8/P8>5,5,IF(V8/P8=0,0.0000001,V8/P8))) -> 1e-07 | Y8: =IFERROR(VLOOKUP(B8,'Факт продаж'!AB:AH,7,0),"-") -> - | Z8: =IF(AND(F8=0,V8>0),5,IF(V8/F8>5,5,IF(V8/F8=0,0.0000001,V8/F8))) -> #DIV/0! | AB8: =IFERROR(VLOOKUP(VALUE(IF(L8<1,1,0)&IF(J8<'Факт продаж'!$M$24,0,1)),$AB$1:$AC$4,2,FALSE),"НЕТ ПРОДАЖ") -> Темная лошадка | AC8: =IFERROR(VLOOKUP(VALUE(IF(R8<1,1,0)&IF(P8<'Факт продаж'!$V$24,0,1)),$AB$1:$AC$4,2,FALSE),"НЕТ ПРОДАЖ") -> Собака | AD8: =IFERROR(VLOOKUP(VALUE(IF(X8<1,1,0)&IF(V8<'Факт продаж'!$AE$24,0,1)),$AB$1:$AC$4,2,FALSE),"НЕТ ПРОДАЖ") -> Собака | AE8: =IFERROR(VLOOKUP(VALUE(IF(Z8<1,1,0)&IF(V8<'Факт продаж'!$AE$24,0,1)),$AB$1:$AC$4,2,FALSE),"НЕТ ПРОДАЖ") -> НЕТ ПРОДАЖ | AF8: =VLOOKUP(B8,'ABC расчет'!B:G,6,0) -> C | AG8: =VLOOKUP(B8,'ABC расчет'!K:P,6,0) -> C | AH8: =VLOOKUP(B8,'ABC расчет'!T:Y,6,0) -> C | AI8: =VLOOKUP(B8,'ABC расчет'!AC:AH,6,0) -> C
A9: КОМПЛЕКТУЮЩИЕ СТОЛОВ, КРЕСЕЛ И СТУЛЬЕВ ОБЕДЕННЫХ | B9: РАМА CFS | C9: =IFERROR(VLOOKUP(B9,'Факт продаж'!A:B,2,0),"нет продаж") -> 80 | D9: =IFERROR(VLOOKUP(B9,'Факт продаж'!A:C,3,0),"нет продаж") -> 29918.327 | E9: =IFERROR(VLOOKUP(B9,'Факт продаж'!A:E,5,0),"нет продаж") -> 16304.501 | F9: =IFERROR(VLOOKUP(B9,'Факт продаж'!A:C,3,0)/SUM('План Антонова'!$C$11:$C$13),0) -> 0.00022717303 | G9: =IFERROR(VLOOKUP(B9,'Факт продаж'!J:K,2,0),"нет продаж") -> 15 | H9: =IFERROR(VLOOKUP(B9,'Факт продаж'!J:L,3,0),"нет продаж") -> 7035.2 | I9: =IFERROR(VLOOKUP(B9,'Факт продаж'!J:N,5,0),"нет продаж") -> 1246.4195 | J9: =IFERROR(VLOOKUP(B9,'Факт продаж'!J:L,3,0)/SUM('План Антонова'!$C$14:$C$16),0) -> 4.8577073e-05 | K9: =IFERROR(VLOOKUP(B9,'Факт продаж'!J:O,6,0),"-") -> -0.92355365 | L9: =IF(AND(F9=0,J9>0),5,IF(J9/F9>5,5,IF(J9/F9=0,0.0000001,J9/F9))) -> 0.21383292 | M9: =IFERROR(VLOOKUP(B9,'Факт продаж'!S:T,2,0),"нет продаж") -> 10 | N9: =IFERROR(VLOOKUP(B9,'Факт продаж'!S:U,3,0),"нет продаж") -> 5815 | O9: =IFERROR(VLOOKUP(B9,'Факт продаж'!S:W,5,0),"нет продаж") -> 1102.8124 | P9: =IFERROR(VLOOKUP(B9,'Факт продаж'!S:U,3,0)/SUM('План Антонова'!$C$17:$C$19),0) -> 3.5419458e-05 | Q9: =IFERROR(VLOOKUP(B9,'Факт продаж'!S:X,6,0),"-") -> -0.11521569 | R9: =IF(AND(J9=0,P9>0),5,IF(P9/J9>5,5,IF(P9/J9=0,0.0000001,P9/J9))) -> 0.72913941 | S9: =IFERROR(VLOOKUP(B9,'Факт продаж'!AB:AD,2,0),"нет продаж") -> нет продаж | T9: =IFERROR(VLOOKUP(B9,'Факт продаж'!AB:AD,3,0),"нет продаж") -> нет продаж | U9: =IFERROR(VLOOKUP(B9,'Факт продаж'!AB:AF,5,0),"нет продаж") -> нет продаж | V9: =IFERROR(VLOOKUP(B9,'Факт продаж'!AB:AD,3,0)/SUM('План Антонова'!$C$20:$C$22),0) -> 0 | W9: =IFERROR(VLOOKUP(B9,'Факт продаж'!AB:AG,6,0),"-") -> - | X9: =IF(AND(P9=0,V9>0),5,IF(V9/P9>5,5,IF(V9/P9=0,0.0000001,V9/P9))) -> 1e-07 | Y9: =IFERROR(VLOOKUP(B9,'Факт продаж'!AB:AH,7,0),"-") -> - | Z9: =IF(AND(F9=0,V9>0),5,IF(V9/F9>5,5,IF(V9/F9=0,0.0000001,V9/F9))) -> 1e-07 | AB9: =IFERROR(VLOOKUP(VALUE(IF(L9<1,1,0)&IF(J9<'Факт продаж'!$M$24,0,1)),$AB$1:$AC$4,2,FALSE),"НЕТ ПРОДАЖ") -> Собака | AC9: =IFERROR(VLOOKUP(VALUE(IF(R9<1,1,0)&IF(P9<'Факт продаж'!$V$24,0,1)),$AB$1:$AC$4,2,FALSE),"НЕТ ПРОДАЖ") -> Собака | AD9: =IFERROR(VLOOKUP(VALUE(IF(X9<1,1,0)&IF(V9<'Факт продаж'!$AE$24,0,1)),$AB$1:$AC$4,2,FALSE),"НЕТ ПРОДАЖ") -> Собака | AE9: =IFERROR(VLOOKUP(VALUE(IF(Z9<1,1,0)&IF(V9<'Факт продаж'!$AE$24,0,1)),$AB$1:$AC$4,2,FALSE),"НЕТ ПРОДАЖ") -> Собака | AF9: =VLOOKUP(B9,'ABC расчет'!B:G,6,0) -> A | AG9: =VLOOKUP(B9,'ABC расчет'!K:P,6,0) -> C | AH9: =VLOOKUP(B9,'ABC расчет'!T:Y,6,0) -> C | AI9: =VLOOKUP(B9,'ABC расчет'!AC:AH,6,0) -> C
A10: КОМПЛЕКТУЮЩИЕ СТОЛОВ, КРЕСЕЛ И СТУЛЬЕВ ОБЕДЕННЫХ | B10: РАМА NXL | C10: =IFERROR(VLOOKUP(B10,'Факт продаж'!A:B,2,0),"нет продаж") -> нет продаж | D10: =IFERROR(VLOOKUP(B10,'Факт продаж'!A:C,3,0),"нет продаж") -> нет продаж | E10: =IFERROR(VLOOKUP(B10,'Факт продаж'!A:E,5,0),"нет продаж") -> нет продаж | F10: =IFERROR(VLOOKUP(B10,'Факт продаж'!A:C,3,0)/SUM('План Антонова'!$C$11:$C$13),0) -> 0 | G10: =IFERROR(VLOOKUP(B10,'Факт продаж'!J:K,2,0),"нет продаж") -> нет продаж | H10: =IFERROR(VLOOKUP(B10,'Факт продаж'!J:L,3,0),"нет продаж") -> нет продаж | I10: =IFERROR(VLOOKUP(B10,'Факт продаж'!J:N,5,0),"нет продаж") -> нет продаж | J10: =IFERROR(VLOOKUP(B10,'Факт продаж'!J:L,3,0)/SUM('План Антонова'!$C$14:$C$16),0) -> 0 | K10: =IFERROR(VLOOKUP(B10,'Факт продаж'!J:O,6,0),"-") -> - | L10: =IF(AND(F10=0,J10>0),5,IF(J10/F10>5,5,IF(J10/F10=0,0.0000001,J10/F10))) -> #DIV/0! | M10: =IFERROR(VLOOKUP(B10,'Факт продаж'!S:T,2,0),"нет продаж") -> нет продаж | N10: =IFERROR(VLOOKUP(B10,'Факт продаж'!S:U,3,0),"нет продаж") -> нет продаж | O10: =IFERROR(VLOOKUP(B10,'Факт продаж'!S:W,5,0),"нет продаж") -> нет продаж | P10: =IFERROR(VLOOKUP(B10,'Факт продаж'!S:U,3,0)/SUM('План Антонова'!$C$17:$C$19),0) -> 0 | Q10: =IFERROR(VLOOKUP(B10,'Факт продаж'!S:X,6,0),"-") -> - | R10: =IF(AND(J10=0,P10>0),5,IF(P10/J10>5,5,IF(P10/J10=0,0.0000001,P10/J10))) -> #DIV/0! | S10: =IFERROR(VLOOKUP(B10,'Факт продаж'!AB:AD,2,0),"нет продаж") -> нет продаж | T10: =IFERROR(VLOOKUP(B10,'Факт продаж'!AB:AD,3,0),"нет продаж") -> нет продаж | U10: =IFERROR(VLOOKUP(B10,'Факт продаж'!AB:AF,5,0),"нет продаж") -> нет продаж | V10: =IFERROR(VLOOKUP(B10,'Факт продаж'!AB:AD,3,0)/SUM('План Антонова'!$C$20:$C$22),0) -> 0 | W10: =IFERROR(VLOOKUP(B10,'Факт продаж'!AB:AG,6,0),"-") -> - | X10: =IF(AND(P10=0,V10>0),5,IF(V10/P10>5,5,IF(V10/P10=0,0.0000001,V10/P10))) -> #DIV/0! | Y10: =IFERROR(VLOOKUP(B10,'Факт продаж'!AB:AH,7,0),"-") -> - | Z10: =IF(AND(F10=0,V10>0),5,IF(V10/F10>5,5,IF(V10/F10=0,0.0000001,V10/F10))) -> #DIV/0! | AB10: =IFERROR(VLOOKUP(VALUE(IF(L10<1,1,0)&IF(J10<'Факт продаж'!$M$24,0,1)),$AB$1:$AC$4,2,FALSE),"НЕТ ПРОДАЖ") -> НЕТ ПРОДАЖ | AC10: =IFERROR(VLOOKUP(VALUE(IF(R10<1,1,0)&IF(P10<'Факт продаж'!$V$24,0,1)),$AB$1:$AC$4,2,FALSE),"НЕТ ПРОДАЖ") -> НЕТ ПРОДАЖ | AD10: =IFERROR(VLOOKUP(VALUE(IF(X10<1,1,0)&IF(V10<'Факт продаж'!$AE$24,0,1)),$AB$1:$AC$4,2,FALSE),"НЕТ ПРОДАЖ") -> НЕТ ПРОДАЖ | AE10: =IFERROR(VLOOKUP(VALUE(IF(Z10<1,1,0)&IF(V10<'Факт продаж'!$AE$24,0,1)),$AB$1:$AC$4,2,FALSE),"НЕТ ПРОДАЖ") -> НЕТ ПРОДАЖ | AF10: =VLOOKUP(B10,'ABC расчет'!B:G,6,0) -> C | AG10: =VLOOKUP(B10,'ABC расчет'!K:P,6,0) -> C | AH10: =VLOOKUP(B10,'ABC расчет'!T:Y,6,0) -> C | AI10: =VLOOKUP(B10,'ABC расчет'!AC:AH,6,0) -> C | AL10: Есть продажи по ГП
A11: КРЕСЛА ДЕТСКИЕ | B11: MINISIT | C11: =IFERROR(VLOOKUP(B11,'Факт продаж'!A:B,2,0),"нет продаж") -> нет продаж | D11: =IFERROR(VLOOKUP(B11,'Факт продаж'!A:C,3,0),"нет продаж") -> нет продаж | E11: =IFERROR(VLOOKUP(B11,'Факт продаж'!A:E,5,0),"нет продаж") -> нет продаж | F11: =IFERROR(VLOOKUP(B11,'Факт продаж'!A:C,3,0)/SUM('План Антонова'!$C$11:$C$13),0) -> 0 | G11: =IFERROR(VLOOKUP(B11,'Факт продаж'!J:K,2,0),"нет продаж") -> нет продаж | H11: =IFERROR(VLOOKUP(B11,'Факт продаж'!J:L,3,0),"нет продаж") -> нет продаж | I11: =IFERROR(VLOOKUP(B11,'Факт продаж'!J:N,5,0),"нет продаж") -> нет продаж | J11: =IFERROR(VLOOKUP(B11,'Факт продаж'!J:L,3,0)/SUM('План Антонова'!$C$14:$C$16),0) -> 0 | K11: =IFERROR(VLOOKUP(B11,'Факт продаж'!J:O,6,0),"-") -> - | L11: =IF(AND(F11=0,J11>0),5,IF(J11/F11>5,5,IF(J11/F11=0,0.0000001,J11/F11))) -> #DIV/0! | M11: =IFERROR(VLOOKUP(B11,'Факт продаж'!S:T,2,0),"нет продаж") -> нет продаж | N11: =IFERROR(VLOOKUP(B11,'Факт продаж'!S:U,3,0),"нет продаж") -> нет продаж | O11: =IFERROR(VLOOKUP(B11,'Факт продаж'!S:W,5,0),"нет продаж") -> нет продаж | P11: =IFERROR(VLOOKUP(B11,'Факт продаж'!S:U,3,0)/SUM('План Антонова'!$C$17:$C$19),0) -> 0 | Q11: =IFERROR(VLOOKUP(B11,'Факт продаж'!S:X,6,0),"-") -> - | R11: =IF(AND(J11=0,P11>0),5,IF(P11/J11>5,5,IF(P11/J11=0,0.0000001,P11/J11))) -> #DIV/0! | S11: =IFERROR(VLOOKUP(B11,'Факт продаж'!AB:AD,2,0),"нет продаж") -> нет продаж | T11: =IFERROR(VLOOKUP(B11,'Факт продаж'!AB:AD,3,0),"нет продаж") -> нет продаж | U11: =IFERROR(VLOOKUP(B11,'Факт продаж'!AB:AF,5,0),"нет продаж") -> нет продаж | V11: =IFERROR(VLOOKUP(B11,'Факт продаж'!AB:AD,3,0)/SUM('План Антонова'!$C$20:$C$22),0) -> 0 | W11: =IFERROR(VLOOKUP(B11,'Факт продаж'!AB:AG,6,0),"-") -> - | X11: =IF(AND(P11=0,V11>0),5,IF(V11/P11>5,5,IF(V11/P11=0,0.0000001,V11/P11))) -> #DIV/0! | Y11: =IFERROR(VLOOKUP(B11,'Факт продаж'!AB:AH,7,0),"-") -> - | Z11: =IF(AND(F11=0,V11>0),5,IF(V11/F11>5,5,IF(V11/F11=0,0.0000001,V11/F11))) -> #DIV/0! | AB11: =IFERROR(VLOOKUP(VALUE(IF(L11<1,1,0)&IF(J11<'Факт продаж'!$M$24,0,1)),$AB$1:$AC$4,2,FALSE),"НЕТ ПРОДАЖ") -> НЕТ ПРОДАЖ | AC11: =IFERROR(VLOOKUP(VALUE(IF(R11<1,1,0)&IF(P11<'Факт продаж'!$V$24,0,1)),$AB$1:$AC$4,2,FALSE),"НЕТ ПРОДАЖ") -> НЕТ ПРОДАЖ | AD11: =IFERROR(VLOOKUP(VALUE(IF(X11<1,1,0)&IF(V11<'Факт продаж'!$AE$24,0,1)),$AB$1:$AC$4,2,FALSE),"НЕТ ПРОДАЖ") -> НЕТ ПРОДАЖ | AE11: =IFERROR(VLOOKUP(VALUE(IF(Z11<1,1,0)&IF(V11<'Факт продаж'!$AE$24,0,1)),$AB$1:$AC$4,2,FALSE),"НЕТ ПРОДАЖ") -> НЕТ ПРОДАЖ | AF11: =VLOOKUP(B11,'ABC расчет'!B:G,6,0) -> C | AG11: =VLOOKUP(B11,'ABC расчет'!K:P,6,0) -> C | AH11: =VLOOKUP(B11,'ABC расчет'!T:Y,6,0) -> C | AI11: =VLOOKUP(B11,'ABC расчет'!AC:AH,6,0) -> C | AL11: Новинка
A12: КРЕСЛА ОПЕРАТОРСКИЕ | B12: NAVIGO | C12: =IFERROR(VLOOKUP(B12,'Факт продаж'!A:B,2,0),"нет продаж") -> 71 | D12: =IFERROR(VLOOKUP(B12,'Факт продаж'!A:C,3,0),"нет продаж") -> 427449.99 | E12: =IFERROR(VLOOKUP(B12,'Факт продаж'!A:E,5,0),"нет продаж") -> 160292.53 | F12: =IFERROR(VLOOKUP(B12,'Факт продаж'!A:C,3,0)/SUM('План Антонова'!$C$11:$C$13),0) -> 0.003245673 | G12: =IFERROR(VLOOKUP(B12,'Факт продаж'!J:K,2,0),"нет продаж") -> 3 | H12: =IFERROR(VLOOKUP(B12,'Факт продаж'!J:L,3,0),"нет продаж") -> 20065.1 | I12: =IFERROR(VLOOKUP(B12,'Факт продаж'!J:N,5,0),"нет продаж") -> 8373.5612 | J12: =IFERROR(VLOOKUP(B12,'Факт продаж'!J:L,3,0)/SUM('План Антонова'!$C$14:$C$16),0) -> 0.00013854671 | K12: =IFERROR(VLOOKUP(B12,'Факт продаж'!J:O,6,0),"-") -> -0.94776075 | L12: =IF(AND(F12=0,J12>0),5,IF(J12/F12>5,5,IF(J12/F12=0,0.0000001,J12/F12))) -> 0.042686589 | M12: =IFERROR(VLOOKUP(B12,'Факт продаж'!S:T,2,0),"нет продаж") -> 1 | N12: =IFERROR(VLOOKUP(B12,'Факт продаж'!S:U,3,0),"нет продаж") -> 9082.5 | O12: =IFERROR(VLOOKUP(B12,'Факт продаж'!S:W,5,0),"нет продаж") -> 4485.7401 | P12: =IFERROR(VLOOKUP(B12,'Факт продаж'!S:U,3,0)/SUM('План Антонова'!$C$17:$C$19),0) -> 5.5321965e-05 | Q12: =IFERROR(VLOOKUP(B12,'Факт продаж'!S:X,6,0),"-") -> -0.46429721 | R12: =IF(AND(J12=0,P12>0),5,IF(P12/J12>5,5,IF(P12/J12=0,0.0000001,P12/J12))) -> 0.3993019 | S12: =IFERROR(VLOOKUP(B12,'Факт продаж'!AB:AD,2,0),"нет продаж") -> нет продаж | T12: =IFERROR(VLOOKUP(B12,'Факт продаж'!AB:AD,3,0),"нет продаж") -> нет продаж | U12: =IFERROR(VLOOKUP(B12,'Факт продаж'!AB:AF,5,0),"нет продаж") -> нет продаж | V12: =IFERROR(VLOOKUP(B12,'Факт продаж'!AB:AD,3,0)/SUM('План Антонова'!$C$20:$C$22),0) -> 0 | W12: =IFERROR(VLOOKUP(B12,'Факт продаж'!AB:AG,6,0),"-") -> - | X12: =IF(AND(P12=0,V12>0),5,IF(V12/P12>5,5,IF(V12/P12=0,0.0000001,V12/P12))) -> 1e-07 | Y12: =IFERROR(VLOOKUP(B12,'Факт продаж'!AB:AH,7,0),"-") -> - | Z12: =IF(AND(F12=0,V12>0),5,IF(V12/F12>5,5,IF(V12/F12=0,0.0000001,V12/F12))) -> 1e-07 | AB12: =IFERROR(VLOOKUP(VALUE(IF(L12<1,1,0)&IF(J12<'Факт продаж'!$M$24,0,1)),$AB$1:$AC$4,2,FALSE),"НЕТ ПРОДАЖ") -> Собака | AC12: =IFERROR(VLOOKUP(VALUE(IF(R12<1,1,0)&IF(P12<'Факт продаж'!$V$24,0,1)),$AB$1:$AC$4,2,FALSE),"НЕТ ПРОДАЖ") -> Собака | AD12: =IFERROR(VLOOKUP(VALUE(IF(X12<1,1,0)&IF(V12<'Факт продаж'!$AE$24,0,1)),$AB$1:$AC$4,2,FALSE),"НЕТ ПРОДАЖ") -> Собака | AE12: =IFERROR(VLOOKUP(VALUE(IF(Z12<1,1,0)&IF(V12<'Факт продаж'!$AE$24,0,1)),$AB$1:$AC$4,2,FALSE),"НЕТ ПРОДАЖ") -> Собака | AF12: =VLOOKUP(B12,'ABC расчет'!B:G,6,0) -> A | AG12: =VLOOKUP(B12,'ABC расчет'!K:P,6,0) -> C | AH12: =VLOOKUP(B12,'ABC расчет'!T:Y,6,0) -> C | AI12: =VLOOKUP(B12,'ABC расчет'!AC:AH,6,0) -> C
A13: КРЕСЛА РУКОВОДИТЕЛЯ | B13: FLORIDA | C13: =IFERROR(VLOOKUP(B13,'Факт продаж'!A:B,2,0),"нет продаж") -> 7 | D13: =IFERROR(VLOOKUP(B13,'Факт продаж'!A:C,3,0),"нет продаж") -> 36352.268 | E13: =IFERROR(VLOOKUP(B13,'Факт продаж'!A:E,5,0),"нет продаж") -> 18826.819 | F13: =IFERROR(VLOOKUP(B13,'Факт продаж'!A:C,3,0)/SUM('План Антонова'!$C$11:$C$13),0) -> 0.00027602662 | G13: =IFERROR(VLOOKUP(B13,'Факт продаж'!J:K,2,0),"нет продаж") -> нет продаж | H13: =IFERROR(VLOOKUP(B13,'Факт продаж'!J:L,3,0),"нет продаж") -> нет продаж | I13: =IFERROR(VLOOKUP(B13,'Факт продаж'!J:N,5,0),"нет продаж") -> нет продаж | J13: =IFERROR(VLOOKUP(B13,'Факт продаж'!J:L,3,0)/SUM('План Антонова'!$C$14:$C$16),0) -> 0 | K13: =IFERROR(VLOOKUP(B13,'Факт продаж'!J:O,6,0),"-") -> - | L13: =IF(AND(F13=0,J13>0),5,IF(J13/F13>5,5,IF(J13/F13=0,0.0000001,J13/F13))) -> 1e-07 | M13: =IFERROR(VLOOKUP(B13,'Факт продаж'!S:T,2,0),"нет продаж") -> нет продаж | N13: =IFERROR(VLOOKUP(B13,'Факт продаж'!S:U,3,0),"нет продаж") -> нет продаж | O13: =IFERROR(VLOOKUP(B13,'Факт продаж'!S:W,5,0),"нет продаж") -> нет продаж | P13: =IFERROR(VLOOKUP(B13,'Факт продаж'!S:U,3,0)/SUM('План Антонова'!$C$17:$C$19),0) -> 0 | Q13: =IFERROR(VLOOKUP(B13,'Факт продаж'!S:X,6,0),"-") -> - | R13: =IF(AND(J13=0,P13>0),5,IF(P13/J13>5,5,IF(P13/J13=0,0.0000001,P13/J13))) -> #DIV/0! | S13: =IFERROR(VLOOKUP(B13,'Факт продаж'!AB:AD,2,0),"нет продаж") -> нет продаж | T13: =IFERROR(VLOOKUP(B13,'Факт продаж'!AB:AD,3,0),"нет продаж") -> нет продаж | U13: =IFERROR(VLOOKUP(B13,'Факт продаж'!AB:AF,5,0),"нет продаж") -> нет продаж | V13: =IFERROR(VLOOKUP(B13,'Факт продаж'!AB:AD,3,0)/SUM('План Антонова'!$C$20:$C$22),0) -> 0 | W13: =IFERROR(VLOOKUP(B13,'Факт продаж'!AB:AG,6,0),"-") -> - | X13: =IF(AND(P13=0,V13>0),5,IF(V13/P13>5,5,IF(V13/P13=0,0.0000001,V13/P13))) -> #DIV/0! | Y13: =IFERROR(VLOOKUP(B13,'Факт продаж'!AB:AH,7,0),"-") -> - | Z13: =IF(AND(F13=0,V13>0),5,IF(V13/F13>5,5,IF(V13/F13=0,0.0000001,V13/F13))) -> 1e-07 | AB13: =IFERROR(VLOOKUP(VALUE(IF(L13<1,1,0)&IF(J13<'Факт продаж'!$M$24,0,1)),$AB$1:$AC$4,2,FALSE),"НЕТ ПРОДАЖ") -> Собака | AC13: =IFERROR(VLOOKUP(VALUE(IF(R13<1,1,0)&IF(P13<'Факт продаж'!$V$24,0,1)),$AB$1:$AC$4,2,FALSE),"НЕТ ПРОДАЖ") -> НЕТ ПРОДАЖ | AD13: =IFERROR(VLOOKUP(VALUE(IF(X13<1,1,0)&IF(V13<'Факт продаж'!$AE$24,0,1)),$AB$1:$AC$4,2,FALSE),"НЕТ ПРОДАЖ") -> НЕТ ПРОДАЖ | AE13: =IFERROR(VLOOKUP(VALUE(IF(Z13<1,1,0)&IF(V13<'Факт продаж'!$AE$24,0,1)),$AB$1:$AC$4,2,FALSE),"НЕТ ПРОДАЖ") -> Собака | AF13: =VLOOKUP(B13,'ABC расчет'!B:G,6,0) -> C | AG13: =VLOOKUP(B13,'ABC расчет'!K:P,6,0) -> C | AH13: =VLOOKUP(B13,'ABC расчет'!T:Y,6,0) -> C | AI13: =VLOOKUP(B13,'ABC расчет'!AC:AH,6,0) -> C
